Workbook
Name таблица: '2.2 ФУНКЦИИ БАЗЫ ДАННЫХ'!$A$2:$I$17

Sheet 1.1 Создание и ведение
A1: Фамилия | B1: Дата рождения | C1: Номер телефона | D1: Количество детей | E1: Отдел | F1: Должность | G1: Дата приема на работу | H1: Оклад (руб) | I1: Пол
A2: Пестова | B2: 29790 | C2: 1245037 | D2: 1 | E2: ОК | F2: Бухгалтер | I2: ж
A3: Парадова | B3: 29572 | C3: 345037 | D3: 2 | E3: ОК | F3: Инспектор | I3: ж
A4: Воронин | B4: 28564 | C4: 1245031 | D4: 3 | E4: ОГЭ | F4: Электрик | I4: м
A5: Радостин | B5: 26783 | C5: 545037 | D5: 1 | E5: ОГМ | F5: Механик | I5: м
A6: Пронин | B6: 30934 | C6: 1245557 | D6: 2 | E6: ОГМ | F6: Механик | I6: м
A7: Аверин | B7: 27544 | C7: 121313 | D7: 1 | E7: ОГМ | F7: Механик | I7: м
A8: Кришин | B8: 28435 | C8: 121212 | D8: 0 | E8: ОГЭ | F8: Электрик | I8: м
A9: Гудков | B9: 28567 | C9: 123421 | D9: 2 | E9: ОГК | F9: Инженер | I9: м

Sheet 1.2 Сортировка
A1: Фамилия | B1: Дата рождения | C1: Номер телефона | D1: Количество детей | E1: Отдел | F1: Должность | G1: Дата приема на работу | H1: Оклад (руб) | I1: Пол
A2: Пестова | B2: 29790 | C2: 1245037 | D2: 1 | E2: ОК | F2: Бухгалтер | I2: ж
A3: Гудков | B3: 28567 | C3: 123421 | D3: 2 | E3: ОГК | F3: Инженер | I3: м
A4: Парадова | B4: 29572 | C4: 345037 | D4: 2 | E4: ОК | F4: Инспектор | I4: ж
A5: Аверин | B5: 27544 | C5: 121 | D5: 1 | E5: ОГМ | F5: Механик | I5: м
A6: Пронин | B6: 30934 | C6: 1245557 | D6: 2 | E6: ОГМ | F6: Механик | I6: м
A7: Радостин | B7: 26783 | C7: 545037 | D7: 1 | E7: ОГМ | F7: Механик | I7: м
A8: Воронин | B8: 28564 | C8: 1245031 | D8: 3 | E8: ОГЭ | F8: Электрик | I8: м
A9: Кришин | B9: 28435 | C9: 121212 | D9: 0 | E9: ОГЭ | F9: Электрик | I9: м

Sheet 1.3 Условное форматирование
A1: Фамилия | B1: Дата рождения | C1: Номер телефона | D1: Количество детей | E1: Отдел | F1: Должность | G1: Дата приема на работу | H1: Оклад (руб) | I1: Пол | K1: Номер приказа | L1: Дата приказа | N1: Фамилия | O1: Дата рождения | P1: Номер телефона | Q1: Количество детей | R1: Отдел | S1: Должность | T1: Дата приема на работу | U1: Оклад (руб) | V1: Пол
A2: Аверин | B2: 27544 | C2: 121313 | D2: 1 | E2: ОГМ | F2: Механик | H2: 9000 | I2: м | K2: Л-123 | L2: 40653 | N2: Аверин | O2: 27544 | P2: 121313 | Q2: 1 | R2: ОГМ | S2: Механик | U2: 9000 | V2: м
A3: Воронин | B3: 28564 | C3: 1245031 | D3: 3 | E3: ОГЭ | F3: Электрик | H3: 55555 | I3: м | K3: Л-124 | L3: 40654 | N3: Воронин | O3: 28564 | P3: 1245031 | Q3: 3 | R3: ОГЭ | S3: Электрик | U3: 55555 | V3: м
A4: Гудков | B4: 28567 | C4: 123421 | D4: 2 | E4: ОГК | F4: Инженер | H4: 120000 | I4: м | K4: Л-125 | L4: 40655 | N4: Гудков | O4: 28567 | P4: 123421 | Q4: 2 | R4: ОГК | S4: Инженер | U4: 25000 | V4: м
A5: Кришин | B5: 28435 | C5: 121212 | D5: 0 | E5: ОГЭ | F5: Электрик | H5: 50000 | I5: м | K5: Л-123 | L5: 40653 | N5: Кришин | O5: 28435 | P5: 121212 | Q5: 0 | R5: ОГЭ | S5: Электрик | U5: 50000 | V5: м
A6: Парадова | B6: 29572 | C6: 345037 | D6: 2 | E6: ОК | F6: Инспектор | H6: 5000 | I6: ж | K6: Л-127 | L6: 40657 | N6: Парадова | O6: 29572 | P6: 345037 | Q6: 2 | R6: ОК | S6: Инспектор | U6: 5000 | V6: ж
A7: Пестова | B7: 29790 | C7: 1245037 | D7: 1 | E7: ОК | F7: Бухгалтер | H7: 80000 | I7: ж | K7: Л-125 | L7: 40655 | N7: Пестова | O7: 29790 | P7: 1245037 | Q7: 1 | R7: ОК | S7: Бухгалтер | U7: 80000 | V7: ж
A8: Пронин | B8: 30934 | C8: 1245557 | D8: 2 | E8: ОГМ | F8: Механик | H8: 30000 | I8: м | K8: Л-129 | L8: 40659 | N8: Пронин | O8: 30934 | P8: 1245557 | Q8: 2 | R8: ОГМ | S8: Механик | U8: 30000 | V8: м
A9: Радостин | B9: 26783 | C9: 545037 | D9: 1 | E9: ОГМ | F9: Механик | H9: 15000 | I9: м | K9: Л-130 | L9: 40660 | N9: Радостин | O9: 26783 | P9: 545037 | Q9: 1 | R9: ОГМ | S9: Механик | U9: 34100 | V9: м
K10: Л-125 | L10: 40655

Sheet 1.4.1 Стандартный фильтр
A1: Фамилия | B1: Дата рождения | C1: Фамилия | D1: Дата рождения | E1: Номер телефона | F1: Количество детей | G1: Отдел | H1: Должность | I1: Дата приема на работу | J1: Оклад (руб) | K1: Пол
A2: Пестова | B2: 29790 | C2: Аверин | D2: 27544 | E2: 121313 | F2: 1 | G2: ОГМ | H2: Механик | J2: 14555 | K2: м
A3: Парадова | B3: 29572 | C3: Воронин | D3: 28564 | E3: 1245031 | F3: 3 | G3: ОГЭ | H3: Электрик | J3: 23233 | K3: м
A4: Воронин | B4: 28564 | C4: Гудков | D4: 28567 | E4: 123421 | F4: 2 | G4: ОГК | H4: Инженер | J4: 122222 | K4: м
A5: Радостин | B5: 26783 | C5: Кришин | D5: 28435 | E5: 121212 | G5: ОГЭ | H5: Электрик | J5: 12222 | K5: м
A6: Пронин | B6: 30934 | C6: Парадова | D6: 29572 | E6: 345037 | F6: 2 | G6: ОК | H6: Инспектор | J6: 5000 | K6: ж
A7: Аверин | B7: 27544 | C7: Пестова | D7: 29790 | E7: 1245037 | F7: 1 | G7: ОК | H7: Бухгалтер | J7: 12341 | K7: ж
A8: Кришин | B8: 28435 | C8: Пронин | D8: 30934 | E8: 1245557 | F8: 2 | G8: ОГМ | H8: Механик | J8: 23322 | K8: м
A9: Гудков | B9: 28567 | C9: Радостин | D9: 26783 | E9: 545037 | F9: 1 | G9: ОГМ | H9: Механик | J9: 7111 | K9: м

Sheet 1.4.2 Расширенный фильтр
A1: Фамилия | B1: Дата рождения | C1: Номер телефона | D1: Количество детей | E1: Отдел | F1: Должность | G1: Дата приема на работу | H1: Оклад (руб) | I1: Пол | J1: улица
A2: Пестова | B2: 29790 | C2: 1245037 | D2: 1 | E2: ОК | F2: Бухгалтер | H2: 12000 | I2: ж | J2: Строителей
A3: Парадова | B3: 29572 | C3: 345037 | D3: 2 | E3: ОК | F3: Инспектор | H3: 17000 | I3: ж
A4: Воронин | B4: 28564 | C4: 3645031 | D4: 3 | E4: ОГЭ | F4: Электрик | H4: 22000 | I4: м
A5: Радостин | B5: 26783 | C5: 545037 | D5: 1 | E5: ОГМ | F5: Механик | H5: 47000 | I5: м | J5: Строителей
A6: Пронин | B6: 30934 | C6: 1245557 | D6: 2 | E6: ОГМ | F6: Механик | H6: 32000 | I6: м
A7: Аверин | B7: 27544 | C7: 121313 | D7: 1 | E7: ОГМ | F7: Механик | H7: 37000 | I7: м
A8: Кришин | B8: 28435 | C8: 121212 | D8: 0 | E8: ОГЭ | F8: Электрик | H8: 42000 | I8: м
A9: Гудков | B9: 28567 | C9: 363421 | D9: 2 | E9: ОГК | F9: Инженер | H9: 3555 | I9: м
A13: Фамилия | B13: Дата рождения | C13: Номер телефона | D13: Количество детей | E13: Отдел | F13: Должность | G13: Дата приема на работу | H13: Оклад (руб) | I13: Пол | J13: улица
A14: Пестова | B14: >12.11.1979
A15: Воронин | B15: >12.11.1979
A16: а
A17: б
A25: Фамилия | B25: Дата рождения | C25: Номер телефона | D25: Количество детей | E25: Отдел | F25: Должность | G25: Дата приема на работу | H25: Оклад (руб) | I25: Пол | J25: улица
A26: Пестова | B26: 29790 | C26: 1245037 | D26: 1 | E26: ОК | F26: Бухгалтер | H26: 12000 | I26: ж | J26: Строителей
A27: Аверин | B27: 27544 | C27: 121313 | D27: 1 | E27: ОГМ | F27: Механик | H27: 37000 | I27: м

Sheet Структура 1.5
B1: январь | C1: февраль | D1: март | E1: 1 кв. | F1: апрель | G1: май | H1: июнь | I1: 2 кв. | J1: Общие итоги за 1-2 кв.
A2: Отдел 1
A3: ПТР 1 | B3: 706 | C3: 274 | D3: 674 | E3: =SUM(B3:D3) -> 1654 | F3: 734 | G3: 315 | H3: 37 | I3: =SUM(F3:H3) -> 1086 | J3: =SUM(E3+I3) -> 2740
A4: ПТР 2 | B4: 964 | C4: 909 | D4: 19 | E4: =SUM(B4:D4) -> 1892 | F4: 884 | G4: 906 | H4: 920 | I4: =SUM(F4:H4) -> 2710 | J4: =SUM(E4+I4) -> 4602
A5: ПТР 3 | B5: 734 | C5: 315 | D5: 37 | E5: =SUM(B5:D5) -> 1086 | F5: 917 | G5: 894 | H5: 766 | I5: =SUM(F5:H5) -> 2577 | J5: =SUM(E5+I5) -> 3663
A6: ПТР 4 | B6: 884 | C6: 906 | D6: 920 | E6: =SUM(B6:D6) -> 2710 | F6: 906 | G6: 706 | H6: 274 | I6: =SUM(F6:H6) -> 1886 | J6: =SUM(E6+I6) -> 4596
A7: ПТР 5 | B7: 917 | C7: 894 | D7: 766 | E7: =SUM(B7:D7) -> 2577 | F7: 894 | G7: 964 | H7: 909 | I7: =SUM(F7:H7) -> 2767 | J7: =SUM(E7+I7) -> 5344
A8: Отдел 1 всего | B8: =SUM(B3:B7) -> 4205 | C8: =SUM(C3:C7) -> 3298 | D8: =SUM(D3:D7) -> 2416 | E8: =SUM(B8:D8) -> 9919 | F8: =SUM(F3:F7) -> 4335 | G8: =SUM(G3:G7) -> 3785 | H8: =SUM(H3:H7) -> 2906 | I8: =SUM(F8:H8) -> 11026 | J8: =SUM(E8+I8) -> 20945
A10: Отдел 2 | J10: =SUM(E10+I10) -> 0
A11: ПТР 2 | B11: 119 | C11: 202 | D11: 128 | E11: =SUM(B11:D11) -> 449 | F11: 734 | G11: 315 | H11: 37 | I11: =SUM(F11:H11) -> 1086 | J11: =SUM(E11+I11) -> 1535
A12: ПТР 4 | B12: 361 | C12: 84 | D12: 569 | E12: =SUM(B12:D12) -> 1014 | F12: 884 | G12: 906 | H12: 920 | I12: =SUM(F12:H12) -> 2710 | J12: =SUM(E12+I12) -> 3724
A13: ПТР 7 | B13: 927 | C13: 866 | D13: 769 | E13: =SUM(B13:D13) -> 2562 | F13: 917 | G13: 894 | H13: 766 | I13: =SUM(F13:H13) -> 2577 | J13: =SUM(E13+I13) -> 5139
A14: Отдел 2 всего | B14: =SUM(B11:B13) -> 1407 | C14: =SUM(C11:C13) -> 1152 | D14: =SUM(D11:D13) -> 1466 | E14: =SUM(B14:D14) -> 4025 | F14: =SUM(F11:F13) -> 2535 | G14: =SUM(G11:G13) -> 2115 | H14: =SUM(H11:H13) -> 1723 | I14: =SUM(F14:H14) -> 6373 | J14: =SUM(E14+I14) -> 10398
A15: ИТОГО | B15: =SUM(B8,B14) -> 5612 | C15: =SUM(C8,C14) -> 4450 | D15: =SUM(D8,D14) -> 3882 | E15: =SUM(E8,E14) -> 13944 | F15: =SUM(F8,F14) -> 6870 | G15: =SUM(G8,G14) -> 5900 | H15: =SUM(H8,H14) -> 4629 | I15: =SUM(I8,I14) -> 17399 | J15: =SUM(E15+I15) -> 31343

Sheet 2.1 Промежуточные итоги
A1: Фамилия | B1: Дата рождения | C1: Номер телефона | D1: Количество детей | E1: Отдел | F1: Должность | G1: Дата приема на работу | H1: Оклад (руб) | I1: Пол
A2: Пестова | B2: 29790 | C2: 1245037 | D2: 1 | E2: ОК | F2: Бухгалтер | H2: 12000 | I2: ж
D3: ОК Итог | E3: =SUBTOTAL(9,E2:E2) -> 0 | H3: =SUBTOTAL(9,H2:H2) -> 12000
D4: ОК Количество | E4: =SUBTOTAL(3,E2:E2) -> 1
E5: Бухгалтер Количество | F5: =SUBTOTAL(3,F2:F2) -> 1
A6: Парадова | B6: 29572 | C6: 345037 | D6: 2 | E6: ОК | F6: Инспектор | H6: 23333 | I6: ж
D7: ОК Итог | E7: =SUBTOTAL(9,E6:E6) -> 0 | H7: =SUBTOTAL(9,H6:H6) -> 23333
D8: ОК Количество | E8: =SUBTOTAL(3,E6:E6) -> 1
E9: Инспектор Количество | F9: =SUBTOTAL(3,F6:F6) -> 1
A10: Воронин | B10: 28564 | C10: 1245031 | D10: 3 | E10: ОГЭ | F10: Электрик | H10: 9999 | I10: м
D11: ОГЭ Итог | E11: =SUBTOTAL(9,E10:E10) -> 0 | H11: =SUBTOTAL(9,H10:H10) -> 9999
D12: ОГЭ Количество | E12: =SUBTOTAL(3,E10:E10) -> 1
E13: Электрик Количество | F13: =SUBTOTAL(3,F10:F10) -> 1
A14: Радостин | B14: 26783 | C14: 545037 | D14: 1 | E14: ОГМ | F14: Механик | H14: 19999 | I14: м
A15: Пронин | B15: 30934 | C15: 1245557 | D15: 2 | E15: ОГМ | F15: Механик | H15: 5000 | I15: м
A16: Аверин | B16: 27544 | C16: 121313 | D16: 1 | E16: ОГМ | F16: Механик | H16: 12000 | I16: м
D17: ОГМ Итог | E17: =SUBTOTAL(9,E14:E16) -> 0 | H17: =SUBTOTAL(9,H14:H16) -> 36999
D18: ОГМ Количество | E18: =SUBTOTAL(3,E14:E16) -> 3
E19: Механик Количество | F19: =SUBTOTAL(3,F14:F16) -> 3
A20: Кришин | B20: 28435 | C20: 121212 | D20: 0 | E20: ОГЭ | F20: Электрик | H20: 4000 | I20: м
D21: ОГЭ Итог | E21: =SUBTOTAL(9,E20:E20) -> 0 | H21: =SUBTOTAL(9,H20:H20) -> 4000
D22: ОГЭ Количество | E22: =SUBTOTAL(3,E20:E20) -> 1
E23: Электрик Количество | F23: =SUBTOTAL(3,F20:F20) -> 1
A24: Гудков | B24: 28567 | C24: 123421 | D24: 2 | E24: ОГК | F24: Инженер | H24: 10000 | I24: м
D25: ОГК Итог | E25: =SUBTOTAL(9,E24:E24) -> 0 | H25: =SUBTOTAL(9,H24:H24) -> 10000
D26: ОГК Количество | E26: =SUBTOTAL(3,E24:E24) -> 1
E27: Инженер Количество | F27: =SUBTOTAL(3,F24:F24) -> 1
D28: Общий итог | E28: =SUBTOTAL(9,E2:E24) -> 0 | H28: =SUBTOTAL(9,H2:H24) -> 96331
E30: Общее количество | F30: =SUBTOTAL(3,F2:F24) -> 8

Sheet 2.2 ФУНКЦИИ БАЗЫ ДАННЫХ
A1: Фамилия | B1: Дата | C1: Номер телефона | D1: Количество детей | E1: Отдел | F1: Должность | G1: Дата приема на работу | H1: Оклад (руб) | I1: Пол
A2: Пестова | B2: 29790 | C2: 1245037 | D2: 1 | E2: ОК | F2: Бухгалтер | H2: 12000 | I2: ж
A3: Парадова | B3: 29572 | C3: 345037 | D3: 2 | E3: ОК | F3: Инспектор | H3: 23333 | I3: ж | K3: средний оклад | L3: Дата
A4: Воронин | B4: 28564 | C4: 1245031 | D4: 3 | E4: ОГЭ | F4: Электрик | H4: 12000 | I4: м | K4: =DAVERAGE(Таблица1[#All],Таблица1[[#All],[Оклад (руб)]],L3:L4) -> #VALUE! | L4: >=12.11.1989
A5: Радостин | B5: 26783 | C5: 545037 | D5: 1 | E5: ОГМ | F5: Механик | H5: 100000 | I5: м
A6: Пронин | B6: 30934 | C6: 1245557 | D6: 2 | E6: ОГМ | F6: Механик | H6: 10000 | I6: м
A7: Аверин | B7: 27544 | C7: 121313 | D7: 1 | E7: ОГМ | F7: Механик | H7: 1111111 | I7: м
A8: Кришин | B8: 28435 | C8: 121212 | D8: 0 | E8: ОГЭ | F8: Электрик | H8: 300303 | I8: м
A9: Гудков | B9: 28567 | C9: 123421 | D9: 2 | E9: ОГК | F9: Инженер | H9: 10000 | I9: м
H10: 12000
H11: 23333
H12: 12000
H13: 100000 | K13: НЕ СДЕЛАНО!!!!!!!
H14: 10000
H15: 1111111
H16: 300303
H17: 10000

Sheet 2.3 Консолидация 
A2: консолидация по расположению
F3: Количество | G3: Стоимость
E4: Электронные Таблицы (Обработка Данных) | F4: =Склад1!$B$2 -> 13 | G4: =Склад1!$C$2 -> 13000
E5: Электронные Таблицы (Обработка Данных) | F5: =Склад2!$B$2 -> 123 | G5: =Склад2!$C$2 -> 12000
F6: =Склад2!$B$13 -> 123 | G6: =Склад2!$C$13 -> 12000
B7: PS3 | F7: =SUM(F4:F6) -> 259 | G7: =SUM(G4:G6) -> 37000
E11: Электронные Таблицы (Обработка Данных) | F11: =Склад1!$B$3 -> 22 | G11: =Склад1!$C$3 -> 20000
E15: Электронные Таблицы (Обработка Данных) | F15: =Склад2!$B$3 -> 232 | G15: =Склад2!$C$3 -> 20000
F18: =Склад2!$B$14 -> 232 | G18: =Склад2!$C$14 -> 20000
B21: PS4 | F21: =SUM(F11:F18) -> 486 | G21: =SUM(G11:G18) -> 60000
E24: Электронные Таблицы (Обработка Данных) | F24: =Склад1!$B$4 -> 12 | G24: =Склад1!$C$4 -> 33
E27: Электронные Таблицы (Обработка Данных) | F27: =Склад2!$B$4 -> 1231 | G27: =Склад2!$C$4 -> 30000
B30: PS5 | F30: =SUM(F24:F27) -> 1243 | G30: =SUM(G24:G27) -> 30033
E33: Электронные Таблицы (Обработка Данных) | F33: =Склад1!$B$5 -> 2 | G33: =Склад1!$C$5 -> 40000
E36: Электронные Таблицы (Обработка Данных) | F36: =Склад2!$B$5 -> 233 | G36: =Склад2!$C$5 -> 40000
B39: PS6 | F39: =SUM(F33:F36) -> 235 | G39: =SUM(G33:G36) -> 80000
E42: Электронные Таблицы (Обработка Данных) | F42: =Склад1!$B$6 -> 2 | G42: =Склад1!$C$6 -> 333
E44: Электронные Таблицы (Обработка Данных) | F44: =Склад2!$B$6 -> 23 | G44: =Склад2!$C$6 -> 50000
B46: PS7 | F46: =SUM(F42:F44) -> 25 | G46: =SUM(G42:G44) -> 50333
E48: Электронные Таблицы (Обработка Данных) | F48: =Склад1!$B$7 -> 3 | G48: =Склад1!$C$7 -> 33
E50: Электронные Таблицы (Обработка Данных) | F50: =Склад2!$B$7 -> 32 | G50: =Склад2!$C$7 -> 60000
B52: PS8 | F52: =SUM(F48:F50) -> 35 | G52: =SUM(G48:G50) -> 60033
E54: Электронные Таблицы (Обработка Данных) | F54: =Склад1!$B$8 -> 1 | G54: =Склад1!$C$8 -> 70000
E56: Электронные Таблицы (Обработка Данных) | F56: =Склад2!$B$8 -> 2 | G56: =Склад2!$C$8 -> 70000
B58: PS9 | F58: =SUM(F54:F56) -> 3 | G58: =SUM(G54:G56) -> 140000
E60: Электронные Таблицы (Обработка Данных) | F60: =Склад1!$B$9 -> 33 | G60: =Склад1!$C$9 -> 80000
E62: Электронные Таблицы (Обработка Данных) | F62: =Склад2!$B$9 -> 2 | G62: =Склад2!$C$9 -> 80000
B64: PS10 | F64: =SUM(F60:F62) -> 35 | G64: =SUM(G60:G62) -> 160000
E65: Электронные Таблицы (Обработка Данных) | F65: =Склад1!$B$10 -> 2 | G65: =Склад1!$C$10 -> 3333
E66: Электронные Таблицы (Обработка Данных) | F66: =Склад2!$B$10 -> 2 | G66: =Склад2!$C$10 -> 90000
B67: PS11 | F67: =SUM(F65:F66) -> 4 | G67: =SUM(G65:G66) -> 93333
E68: Электронные Таблицы (Обработка Данных) | F68: =Склад1!$B$11 -> 11 | G68: =Склад1!$C$11 -> 100000
E69: Электронные Таблицы (Обработка Данных) | F69: =Склад2!$B$11 -> 1 | G69: =Склад2!$C$11 -> 100000
B70: PS12 | F70: =SUM(F68:F69) -> 12 | G70: =SUM(G68:G69) -> 200000
E71: Электронные Таблицы (Обработка Данных) | F71: =Склад1!$B$12 -> 1 | G71: =Склад1!$C$12 -> 110000
E72: Электронные Таблицы (Обработка Данных) | F72: =Склад2!$B$12 -> 1 | G72: =Склад2!$C$12 -> 110000
B73: PS13 | F73: =SUM(F71:F72) -> 2 | G73: =SUM(G71:G72) -> 220000
E74: Электронные Таблицы (Обработка Данных) | F74: =Склад3!$B$2 -> 1232 | G74: =Склад3!$C$2 -> 1000
B75: Dendy1 | F75: =SUM(F74) -> 1232 | G75: =SUM(G74) -> 1000
E76: Электронные Таблицы (Обработка Данных) | F76: =Склад3!$B$3 -> 125 | G76: =Склад3!$C$3 -> 1100
...

Sheet Склад1
A1: Наименование товара | B1: Количество | C1: Стоимость
A2: PS3 | B2: 13 | C2: 13000
A3: PS4 | B3: 22 | C3: 20000
A4: PS5 | B4: 12 | C4: 33
A5: PS6 | B5: 2 | C5: 40000
A6: PS7 | B6: 2 | C6: 333
A7: PS8 | B7: 3 | C7: 33
A8: PS9 | B8: 1 | C8: 70000
A9: PS10 | B9: 33 | C9: 80000
A10: PS11 | B10: 2 | C10: 3333
A11: PS12 | B11: 11 | C11: 100000
A12: PS13 | B12: 1 | C12: 110000

Sheet Склад2
A1: Наименование товара | B1: Количество | C1: Стоимость
A2: PS3 | B2: 123 | C2: 12000
A3: PS4 | B3: 232 | C3: 20000
A4: PS5 | B4: 1231 | C4: 30000
A5: PS6 | B5: 233 | C5: 40000
A6: PS7 | B6: 23 | C6: 50000
A7: PS8 | B7: 32 | C7: 60000
A8: PS9 | B8: 2 | C8: 70000
A9: PS10 | B9: 2 | C9: 80000
A10: PS11 | B10: 2 | C10: 90000
A11: PS12 | B11: 1 | C11: 100000
A12: PS13 | B12: 1 | C12: 110000
A13: PS3 | B13: 123 | C13: 12000
A14: PS4 | B14: 232 | C14: 20000

Sheet Склад3
A1: Наименование товара | B1: Количество | C1: Стоимость
A2: Dendy1 | B2: 1232 | C2: 1000
A3: Dendy2 | B3: 125 | C3: 1100
A4: Dendy3 | B4: 2127 | C4: 1200
A5: Dendy4 | B5: 129 | C5: 1300
A6: Dendy5 | B6: 131 | C6: 1400
A7: Dendy6 | B7: 133 | C7: 1500
A8: Dendy7 | B8: 135 | C8: 1600
A9: Dendy8 | B9: 137 | C9: 1700
A10: Dendy9 | B10: 139 | C10: 1800
A11: Dendy10 | B11: 141 | C11: 1900
A12: Dendy11 | B12: 143 | C12: 2000

Sheet 2.4 Сводная таблица
A1: Дата | B1: Поставщик | C1: Товар | D1: Цена | E1: Колич. | F1: Сумма
A2: 43487 | B2: ООО "Елена" | C2: апельсины | D2: 38 | E2: 30 | F2: 1140
A3: 43487 | B3: ООО "Елена" | C3: бананы | D3: 22 | E3: 30 | F3: 660
A4: 43487 | B4: ЧП Петров | C4: абрикосы | D4: 40 | E4: 10 | F4: 400
A5: 43487 | B5: ЧП Петров | C5: киви | D5: 5 | E5: 50 | F5: 250
A6: 43488 | B6: Сибирь- Манго | C6: картофель | D6: 8 | E6: 120 | F6: 960
A7: 43488 | B7: Сибирь- Манго | C7: лук | D7: 500 | E7: 2 | F7: 1000
A8: 43488 | B8: Сибирь- Манго | C8: капуста | D8: 12 | E8: 40 | F8: 480
A9: 43490 | B9: ООО "Елена" | C9: апельсины | D9: 38 | E9: 20 | F9: 760
A10: 43490 | B10: ООО "Елена" | C10: бананы | D10: 22 | E10: 15 | F10: 330
A11: 43490 | B11: Сибирь- Манго | C11: картофель | D11: 8 | E11: 70 | F11: 560
A12: 43490 | B12: Сибирь- Манго | C12: лук | D12: 500 | E12: 1 | F12: 500
A16: Названия строк | B16: Сумма по полю Сумма
A17: 43487 | B17: 2450
A18: ООО "Елена" | B18: 1800
A19: ЧП Петров | B19: 650
A20: 43488 | B20: 2440
A21: Сибирь- Манго | B21: 2440
A22: 43490 | B22: 2150
A23: ООО "Елена" | B23: 1090
A24: Сибирь- Манго | B24: 1060
A25: Общий итог | B25: 7040
